Workbook

Sheet SALDO CREDOR INSS
B8: SALDO CREDOR INSS - JLE
B10: COMPETÊNCIA | C10: RETENÇÃO NF | D10: UTILIZADO FOLHA | E10: SALDO
B11: 46113 | C11: 120627.34 | D11: 102779.58 | E11: =C11-D11 -> 17847.76
B12: 46143 | C12: 126667.52 | D12: 103847.05 | E12: =C12-D12 -> 22820.47
B13: 46174 | C13: 152096.76 | D13: 95919.98 | E13: =C13-D13 -> 56176.78
B14: 46204 | C14: 135916.62 | D14: 97086.87 | E14: =C14-D14 -> 38829.75
B15: 46235 | C15: 124463.52 | D15: 107769.34 | E15: =C15-D15 -> 16694.18
B16: 46266 | C16: =130875.23 -> 130875.23 | D16: =101785.2 -> 101785.2 | E16: =C16-D16 -> 29090.03
B17: 46296 | E17: =C17-D17 -> 0
B18: 46327 | E18: =C18-D18 -> 0
B19: 46357 | E19: =C19-D19 -> 0
E20: =SUM(E11:E19) -> 181458.97

Sheet PARCELAMENTOS
A1: TAURA AGRONEGOCIOS - IMPOSTOS EM ABERTO - NÃO PARCELADOS NA RECEITA FEDERAL
A2: Imposto | B2: dez/21 | C2: jan/22 | D2: fev/22 | E2: mar/22 | F2: jul/23 | G2: Total
A3: IRPJ | B3: 210224.94 | G3: =Tabela3[[#This Row],[dez/21]]+Tabela3[[#This Row],[jan/22]]+Tabela3[[#This Row],[fev/22]]+Tabela3[[#This Row],[mar/22]]+#REF!+#REF!+#REF!+#REF!+#REF!+#REF!+#REF!+#REF! -> #REF!
A4: CSLL | B4: 80824.65 | G4: =Tabela3[[#This Row],[dez/21]]+Tabela3[[#This Row],[jan/22]]+Tabela3[[#This Row],[fev/22]]+Tabela3[[#This Row],[mar/22]]+#REF!+#REF!+#REF!+#REF!+#REF!+#REF!+#REF!+#REF! -> #REF!
A5: IPI | D5: 186860.2 | E5: 119306.94 | G5: =Tabela3[[#This Row],[dez/21]]+Tabela3[[#This Row],[jan/22]]+Tabela3[[#This Row],[fev/22]]+Tabela3[[#This Row],[mar/22]]+#REF!+#REF!+#REF!+#REF!+#REF!+#REF!+#REF!+#REF! -> #REF!
B6: =SUM(Tabela3[dez/21]) -> 291049.59 | C6: =SUM(Tabela3[jan/22]) -> 0 | D6: =SUM(Tabela3[fev/22]) -> 186860.2 | E6: =SUM(Tabela3[mar/22]) -> 119306.94 | G6: =SUM(Tabela3[Total]) -> #REF!
A8: JLE TELECOMUNICAÇÕES LTDA - IMPOSTOS PARCELADOS
A9: Saldo Devedor Impostos Parcelados - Atualizado em 30.09.2026
A10: Tributo | B10: Data do parcelamento | C10: Valor Saldo a Pagar | D10: Parcelas pagas | E10: Parcelas Faltantes
A11: Parcelamento 07/06/2024 | B11: 45449 | C11: ='PARCELAMENTO 06062024'!Q4 -> 282040.55 | D11: 60/26 | E11: =60-26 -> 34
A12: Parcelamento 05/12/2024 | B12: 45632 | C12: ='PARCELAMENTO 05122024'!Q4 -> 703166.68 | D12: 60/21 | E12: =60-21 -> 39
A13: Parcelamento 06/06/2025 | B13: 45814 | C13: ='PARCELAMENTO 06062025'!Q4 -> 1310298.6 | D13: 60/10 | E13: =60-10 -> 50
A14: Parcelamento 25/11/2025 | B14: 45986 | C14: ='PARCELAMENTO 25112025 '!Q4 -> 77603.11 | D14: 60/8 | E14: =60-8 -> 52
A15: Parcelamento SC 30/08/2025 | B15: 45899 | C15: ='PARCELAMENTO SC'!R4 -> 3855.7 | D15: 48/29 | E15: =48-29 -> 19
C16: =SUM(C11:C15) -> 2376964.7
A18: *** Valores sujeitos a alterações

Sheet PARCELAMENTO 06062024
B3: Código Receita | C3: Apuração | D3: Vencimento | E3: Valor Principal | F3: Valor Multa | G3: Valor Juros | H3: Saldo Devedor | I3: Valor Parcela | J3: Juros | K3: Valor Total | L3: Data Venc. | M3: Amortização | O3: Dívida | P3: Pago | Q3: Saldo | R3: Juros
B4: 1708-06 - REMUNERAÇÃO SERV. PRESTADOS POR PJ | C4: 45231 | D4: 45280 | E4: 10.05 | F4: 2.01 | G4: 0.53 | H4: =SUM(E4,F4,G4) -> 12.59 | I4: 8813.76 | K4: =I4+J4 -> 8813.76 | L4: 45449 | O4: =528825.83 -> 528825.83 | P4: =I4+I5+I6+I7+I8+I9+I10+I11+I12+I13+I14+I15+I16+I17+I18+I19+I20+I21+I22+I23+I24+I25+I26+I27+I28+I29+I30+I31 -> 246785.28 | Q4: =O4-P4 -> 282040.55 | R4: =J5+J6+J7+J8+J9+J10+J11+J12+J13+J14+J15+J16+J17+J18+J19+J20+J21+J22+J23+J24+J25+J26+J27+J28+J29+J30+J31 -> 33892.76
B5: 2089-01 - IRPJ – LUCRO PRESUMIDO | C5: 3º tri/23 | D5: 45230 | E5: 123892.89 | F5: 24778.57 | G5: 8833.56 | H5: =SUM(E5,F5,G5) -> 157505.02 | I5: 8813.76 | J5: 88.13 | K5: =I5+J5 -> 8901.89 | L5: 45504 | M5: =H16-I4 -> 520012.07
B6: 2089-01 - IRPJ – LUCRO PRESUMIDO | C6: 4º tri/23 | D6: 45322 | E6: 118246.84 | F6: 23649.36 | G6: 5143.73 | H6: =SUM(E6,F6,G6) -> 147039.93 | I6: 8813.76 | J6: 168.34 | K6: =I6+J6 -> 8982.1 | L6: 45535 | M6: =M5-I6 -> 511198.31 | O6: AMORTIZAÇÃO DA DÍVIDA | Q6: =(Q4/O4)-1 -> -0.46666646
B7: 2172-01 - COFINS SOBRE FATURAMENTO | C7: 45200 | D7: 45254 | E7: 31551.31 | F7: 6310.26 | G7: 1959.33 | H7: =SUM(E7,F7,G7) -> 39820.9 | I7: 8813.76 | J7: 245.02 | K7: =I7+J7 -> 9058.78 | L7: 45565 | M7: =M6-I7 -> 502384.55
B8: 2172-01 - COFINS SOBRE FATURAMENTO | C8: 45231 | D8: 45282 | E8: 7183.15 | F8: 1436.63 | G8: 382.14 | H8: =SUM(E8,F8,G8) -> 9001.92 | I8: 8813.76 | J8: 319.05 | K8: =I8+J8 -> 9132.81 | L8: 45596 | M8: =M7-I8 -> 493570.79
B9: 2172-01 - COFINS SOBRE FATURAMENTO | C9: 45292 | D9: 45345 | E9: 38900.44 | F9: 7780.08 | G9: 1380.96 | H9: =SUM(E9,F9,G9) -> 48061.48 | I9: 8813.76 | J9: 401.02 | K9: =I9+J9 -> 9214.78 | L9: 45626 | M9: =M8-I9 -> 484757.03 | O9: IMPOSTO SOBRE SERVIÇO TOMADO
B10: 2372-01 - CSLL SOBRE FATURAMENTO | C10: 3º tri/23 | D10: 45230 | E10: 44999.89 | F10: 8999.97 | G10: 3208.49 | H10: =SUM(E10,F10,G10) -> 57208.35 | I10: 8813.76 | J10: 470.65 | K10: =I10+J10 -> 9284.41 | L10: 45657 | M10: =M9-I10 -> 475943.27 | O10: IMPOSTO SOBRE O FATURAMENTO
B11: 2372-01 - CSLL SOBRE FATURAMENTO | C11: 4º tri/23 | D11: 45322 | E11: 41044.81 | F11: 8208.96 | G11: 1785.44 | H11: =SUM(E11,F11,G11) -> 51039.21 | I11: 8813.76 | J11: 552.62 | K11: =I11+J11 -> 9366.38 | L11: 45688 | M11: =M10-I11 -> 467129.51 | O11: RETENÇÃO SOBRE DESPESAS
B12: 3208-06 - IRRF – ALUGUÉIS E ROYALTIES PAGO A PF | C12: 45292 | D12: 45342 | E12: 45.51 | F12: 9.1 | G12: 1.61 | H12: =SUM(E12,F12,G12) -> 56.22 | I12: 8813.76 | J12: 641.64 | K12: =I12+J12 -> 9455.4 | L12: 45716 | M12: =M11-I12 -> 458315.75
B13: 5952-07 - CSLL, COFINS, PIS - RETIDO PJ / PJ | C13: 45231 | D13: 45280 | E13: 31.16 | F13: 6.23 | G13: 1.65 | H13: =SUM(E13,F13,G13) -> 39.04 | I13: 8813.76 | J13: 728.89 | K13: =I13+J13 -> 9542.65 | L13: 45747 | M13: =M12-I13 -> 449501.99
B14: 8109-02 - PIS SOBRE FATURAMENTO | C14: 45200 | D14: 45254 | E14: 6836.12 | F14: 1367.22 | G14: 424.52 | H14: =SUM(E14,F14,G14) -> 8627.86 | I14: 8813.76 | J14: 813.51 | K14: =I14+J14 -> 9627.27 | L14: 45777 | M14: =M13-I14 -> 440688.23
B15: 8109-02 - PIS SOBRE FATURAMENTO | C15: 45292 | D15: 45345 | E15: 8428.43 | F15: 1685.68 | G15: 299.2 | H15: =SUM(E15,F15,G15) -> 10413.31 | I15: 8813.76 | J15: =K15-I15 -> 906.93 | K15: 9720.69 | L15: 45808 | M15: =M14-I15 -> 431874.47
H16: =SUM(H4:H15) -> 528825.83 | I16: 8813.76 | J16: =K16-I16 -> 1007.41 | K16: 9821.17 | L16: 45838 | M16: =M15-I16 -> 423060.71
I17: 8813.76 | J17: =K17-I17 -> 1104.36 | K17: 9918.12 | L17: 45869 | M17: =M16-I17 -> 414246.95
I18: 8813.76 | J18: =K18-I18 -> 1221.18 | K18: 10034.94 | L18: 45900 | M18: =M17-I18 -> 405433.19
I19: 8813.76 | J19: =K19-I19 -> 1319.41 | K19: 10133.17 | L19: 45930 | M19: =M18-I19 -> 396619.43
I20: 8813.76 | J20: =K20-I20 -> 1426.94 | K20: 10240.7 | L20: 45961 | M20: =M19-I20 -> 387805.67
I21: 8813.76 | J21: =K21-I21 -> 1539.76 | K21: 10353.52 | L21: 45991 | M21: =M20-I21 -> 378991.91
I22: 8813.76 | J22: =K22-I22 -> 1739.83 | K22: 10553.59 | L22: 46022 | M22: =M21-I22 -> 370178.15
I23: 8813.76 | J23: =K23-I23 -> 1739.83 | K23: 10553.59 | L23: 46053 | M23: =M22-I23 -> 361364.39
I24: 8813.76 | J24: =K24-I24 -> 1842.07 | K24: 10655.83 | L24: 46081 | M24: =M23-I24 -> 352550.63
I25: 8813.76 | J25: =K25-I25 -> 1930.21 | K25: 10743.97 | L25: 46112 | M25: =M24-I25 -> 343736.87
I26: 8813.76 | J26: =K26-I26 -> 2036.85 | K26: 10850.61 | L26: 46142 | M26: =M25-I26 -> 334923.11
I27: 8813.76 | J27: =K27-I27 -> 2132.92 | K27: 10946.68 | L27: 46173 | M27: =M26-I27 -> 326109.35
I28: 8813.76 | J28: =K28-I28 -> 2227.23 | K28: 11040.99 | L28: 46203 | M28: =M27-I28 -> 317295.59
... I31: 8813.76 | J31: =K31-I31 -> 2529.54 | K31: 11343.3 | L31: 46295 | M31: =M30-I31 -> 290854.31
I32: 8813.76 | K32: =I32+J32 -> 8813.76 | L32: 46326 | M32: =M31-I32 -> 282040.55
I33: 8813.76 | K33: =I33+J33 -> 8813.76 | L33: 46356 | M33: =M32-I33 -> 273226.79
I34: 8813.76 | K34: =I34+J34 -> 8813.76 | L34: 46387 | M34: =M33-I34 -> 264413.03
I35: 8813.76 | K35: =I35+J35 -> 8813.76 | L35: 46418 | M35: =M34-I35 -> 255599.27
I36: 8813.76 | K36: =I36+J36 -> 8813.76 | L36: 46446 | M36: =M35-I36 -> 246785.51
I37: 8813.76 | K37: =I37+J37 -> 8813.76 | L37: 46477 | M37: =M36-I37 -> 237971.75
I38: 8813.76 | K38: =I38+J38 -> 8813.76 | L38: 46507 | M38: =M37-I38 -> 229157.99
I39: 8813.76 | K39: =I39+J39 -> 8813.76 | L39: 46538 | M39: =M38-I39 -> 220344.23
I40: 8813.76 | K40: =I40+J40 -> 8813.76 | L40: 46568 | M40: =M39-I40 -> 211530.47
I41: 8813.76 | K41: =I41+J41 -> 8813.76 | L41: 46599 | M41: =M40-I41 -> 202716.71
I42: 8813.76 | K42: =I42+J42 -> 8813.76 | L42: 46630 | M42: =M41-I42 -> 193902.95
I43: 8813.76 | K43: =I43+J43 -> 8813.76 | L43: 46660 | M43: =M42-I43 -> 185089.19
... I63: 8813.99 | K63: =I63+J63 -> 8813.99 | L63: 47269 | M63: =M62-I63 -> 8813.76
...

Sheet PARCELAMENTO 05122024
B3: Código Receita | C3: Apuração | D3: Vencimento | E3: Valor Principal | F3: Valor Multa | G3: Valor Juros | H3: Saldo Devedor | I3: Valor parcela | J3: Juros | K3: Valor Total | L3: Data Venc. | M3: Amortização | O3: Dívida | P3: Pago | Q3: Saldo | R3: Juros
B4: 0561-07 - IRRF RETIDO NA FONTE - FUNCIONÁRIOS | C4: 45505 | D4: 45554 | E4: 452.04 | F4: 90.4 | G4: 12.29 | H4: =SUM(E4,F4,G4) -> 554.73 | I4: 18504.38 | L4: 45632 | M4: =H125-M4 -> 0 | O4: =SUM(I4:I63) -> 1110263 | P4: =I4+I5+I6+I7+I8+I9+I10+I11+I12+I13+I14+I15+I16+I17+I18+I19+I20+I21+I22+I23+I24+I25 -> 407096.36 | Q4: =O4-P4 -> 703166.68 | R4: =J5+J6+J7+J8+J9+J10+J11+J12+J13+J14+J15+J16+J17+J18+J19+J20+J21+J22+J23+J24+J25 -> 46880.72
B5: 0561-07 - IRRF RETIDO NA FONTE - FUNCIONÁRIOS | C5: 45536 | D5: 45583 | E5: 856 | F5: 171.2 | G5: 15.32 | H5: =SUM(E5,F5,G5) -> 1042.52 | I5: 18504.38 | J5: 185.04 | K5: =I5+J5 -> 18689.42 | L5: 45688 | M5: =I64-I5 -> 1091758.7
B6: 0561-07 - IRRF RETIDO NA FONTE - FUNCIONÁRIOS | C6: 45566 | D6: 45615 | E6: 1200.19 | F6: 240.03 | G6: 12 | H6: =SUM(E6,F6,G6) -> 1452.22 | I6: 18504.38 | J6: 371.93 | K6: =I6+J6 -> 18876.31 | L6: 45716 | M6: =M5-I6 -> 1073254.3 | O6: AMORTIZAÇÃO DA DÍVIDA | Q6: =Q4/O4-1 -> -0.36666659
B7: 0588-06 - IRRF SOBRE A FOLHA | C7: 45505 | D7: 45554 | E7: 169.24 | F7: 33.84 | G7: 4.6 | H7: =SUM(E7,F7,G7) -> 207.68 | I7: 18504.38 | J7: 555.13 | K7: =I7+J7 -> 19059.51 | L7: 45747 | M7: =M6-I7 -> 1054749.9
B8: 0588-06 - IRRF SOBRE A FOLHA | C8: 45536 | D8: 45583 | E8: 169.24 | F8: 33.84 | G8: 3.02 | H8: =SUM(E8,F8,G8) -> 206.1 | I8: 18504.38 | J8: 732.77 | K8: =I8+J8 -> 19237.15 | L8: 45777 | M8: =M7-I8 -> 1036245.5
B9: 0588-06 - IRRF SOBRE A FOLHA | C9: 45566 | D9: 45615 | E9: 169.24 | F9: 33.84 | G9: 1.69 | H9: =SUM(E9,F9,G9) -> 204.77 | I9: 18504.38 | J9: =K9-I9 -> 928.91 | K9: 19433.29 | L9: 45808 | M9: =M8-I9 -> 1017741.1 | O9: DESPESAS SOBRE A FOLHA DE PGTO
B10: 1138-04 - CP PATRONAL - CONTRIBUINTES INDIVIDUAIS | C10: 45505 | D10: 45554 | E10: 2412 | F10: 482.4 | G10: 65.6 | H10: =SUM(E10,F10,G10) -> 2960 | I10: 18504.38 | J10: =K10-I10 -> 1139.86 | K10: 19644.24 | L10: 45838 | M10: =M9-I10 -> 999236.76 | O10: IMPOSTO SOBRE SERVIÇO TOMADO
B11: 1138-01 - CP PATRONAL - EMPREGADOS/AVULSOS | C11: 45505 | D11: 45554 | E11: 17340.28 | F11: 3468.05 | G11: 471.65 | H11: =SUM(E11,F11,G11) -> 21279.98 | I11: 18504.38 | J11: =K11-I11 -> 1343.41 | K11: 19847.79 | L11: 45869 | M11: =M10-I11 -> 980732.38 | O11: IMPOSTO SOBRE O FATURAMENTO
B12: 1138-04 - CP PATRONAL - CONTRIBUINTES INDIVIDUAIS | C12: 45536 | D12: 45583 | E12: 2412 | F12: 482.4 | G12: 43.17 | H12: =SUM(E12,F12,G12) -> 2937.57 | I12: 18504.38 | J12: =K12-I12 -> 1343.41 | K12: 19847.79 | L12: 45900 | M12: =M11-I12 -> 962228
B13: 1138-01 - CP PATRONAL - EMPREGADOS/AVULSOS | C13: 45536 | D13: 45583 | E13: 23268.32 | F13: 4653.66 | G13: 416.5 | H13: =SUM(E13,F13,G13) -> 28338.48 | I13: 18504.38 | J13: =K13-I13 -> 1794.92 | K13: 20299.3 | L13: 45930 | M13: =M12-I13 -> 943723.62
B14: 1138-04 - CP PATRONAL - CONTRIBUINTES INDIVIDUAIS | C14: 45566 | D14: 45615 | E14: 2412 | F14: 482.4 | G14: 24.12 | H14: =SUM(E14,F14,G14) -> 2918.52 | I14: 18504.38 | J14: =K14-I14 -> 2020.67 | K14: 20525.05 | L14: 45961 | M14: =M13-I14 -> 925219.24
B15: 1138-01 - CP PATRONAL - EMPREGADOS/AVULSOS | C15: 45566 | D15: 45615 | E15: 30699.59 | F15: 6139.91 | G15: 306.99 | H15: =SUM(E15,F15,G15) -> 37146.49 | I15: 18504.38 | J15: =K15-I15 -> 2257.53 | K15: 20761.91 | L15: 45991 | M15: =M14-I15 -> 906714.86
B16: 1141-01 - CP PATRONAL - ADICIONAL GILRAT | C16: 45505 | D16: 45554 | E16: 6753.34 | F16: 1350.66 | G16: 183.69 | H16: =SUM(E16,F16,G16) -> 8287.69 | I16: 18504.38 | J16: =K16-I16 -> 2677.58 | K16: 21181.96 | L16: 46022 | M16: =M15-I16 -> 888210.48
B17: 1141-01 - CP PATRONAL - ADICIONAL GILRAT | C17: 45536 | D17: 45583 | E17: 7101.39 | F17: 1420.27 | G17: 127.11 | H17: =SUM(E17,F17,G17) -> 8648.77 | I17: 18504.38 | J17: =K17-I17 -> 2677.58 | K17: 21181.96 | L17: 46053 | M17: =M16-I17 -> 869706.1
B18: 1141-01 - CP PATRONAL - ADICIONAL GILRAT | C18: 45566 | D18: 45615 | E18: 7261.57 | F18: 1452.31 | G18: 72.61 | H18: =SUM(E18,F18,G18) -> 8786.49 | I18: 18504.38 | J18: =K18-I18 -> 2892.23 | K18: 21396.61 | L18: 46081 | M18: =M17-I18 -> 851201.72
B19: 1170-01 - CP TERCEIROS - SALÁRIO EDUCAÇÃO | C19: 45505 | D19: 45554 | E19: 4564.01 | F19: 912.8 | G19: 124.14 | H19: =SUM(E19,F19,G19) -> 5600.95 | I19: 18504.38 | J19: =K19-I19 -> 3077.27 | K19: 21581.65 | L19: 46112 | M19: =M18-I19 -> 832697.34
B20: 1170-01 - CP TERCEIROS - SALÁRIO EDUCAÇÃO | C20: 45536 | D20: 45583 | E20: 4913.74 | F20: 982.74 | G20: 87.95 | H20: =SUM(E20,F20,G20) -> 5984.43 | I20: 18504.38 | J20: =K20-I20 -> 3301.18 | K20: 21805.56 | L20: 46142 | M20: =M19-I20 -> 814192.96
B21: 1170-01 - CP TERCEIROS - SALÁRIO EDUCAÇÃO | C21: 45566 | D21: 45615 | E21: 5431.94 | F21: 1086.38 | G21: 54.31 | H21: =SUM(E21,F21,G21) -> 6572.63 | I21: 18504.38 | J21: =K21-I21 -> 3502.87 | K21: 22007.25 | L21: 46173 | M21: =M20-I21 -> 795688.58
B22: 1176-01 - CP TERCEIROS - INCRA | C22: 45505 | D22: 45554 | E22: 365.11 | F22: 73.02 | G22: 9.93 | H22: =SUM(E22,F22,G22) -> 448.06 | I22: 18504.38 | J22: =K22-I22 -> 3700.87 | K22: 22205.25 | L22: 46203 | M22: =M21-I22 -> 777184.2
B23: 1176-01 - CP TERCEIROS - INCRA | C23: 45536 | D23: 45583 | E23: 393.09 | F23: 78.61 | G23: 7.03 | H23: =SUM(E23,F23,G23) -> 478.73 | I23: 18504.38 | J23: =K23-I23 -> 3908.12 | K23: 22412.5 | L23: 46234 | M23: =M22-I23 -> 758679.82
... B25: 1181-01 - CP TERCEIROS - SENAI | C25: 45505 | D25: 45554 | E25: 761.68 | F25: 152.33 | G25: 20.71 | H25: =SUM(E25,F25,G25) -> 934.72 | I25: 18504.38 | J25: =K25-I25 -> 4335.57 | K25: 22839.95 | L25: 46295 | M25: =M24-I25 -> 721671.06
B26: 1181-01 - CP TERCEIROS - SENAI | C26: 45536 | D26: 45583 | E26: 829.22 | F26: 165.84 | G26: 14.84 | H26: =SUM(E26,F26,G26) -> 1009.9 | I26: 18504.38 | L26: 46326 | M26: =M25-I26 -> 703166.68
B27: 1181-01 - CP TERCEIROS - SENAI | C27: 45566 | D27: 45615 | E27: 909.98 | F27: 181.99 | G27: 9.09 | H27: =SUM(E27,F27,G27) -> 1101.06 | I27: 18504.38 | L27: 46356 | M27: =M26-I27 -> 684662.3
B28: 1184-01 - CP TERCEIROS - SESI | C28: 45505 | D28: 45554 | E28: 1142.53 | F28: 228.5 | G28: 31.07 | H28: =SUM(E28,F28,G28) -> 1402.1 | I28: 18504.38 | L28: 46387 | M28: =M27-I28 -> 666157.92
B29: 1184-01 - CP TERCEIROS - SESI | C29: 45536 | D29: 45583 | E29: 1243.83 | F29: 248.76 | G29: 22.26 | H29: =SUM(E29,F29,G29) -> 1514.85 | I29: 18504.38 | L29: 46418 | M29: =M28-I29 -> 647653.54
B30: 1184-01 - CP TERCEIROS - SESI | C30: 45566 | D30: 45615 | E30: 1364.97 | F30: 272.99 | G30: 13.64 | H30: =SUM(E30,F30,G30) -> 1651.6 | I30: 18504.38 | L30: 46446 | M30: =M29-I30 -> 629149.16
B31: 1200-01 - CP TERCEIROS - SEBRAE | C31: 45505 | D31: 45554 | E31: 1095.35 | F31: 219.07 | G31: 29.79 | H31: =SUM(E31,F31,G31) -> 1344.21 | I31: 18504.38 | L31: 46477 | M31: =M30-I31 -> 610644.78
B32: 1200-01 - CP TERCEIROS - SEBRAE | C32: 45536 | D32: 45583 | E32: 1179.29 | F32: 232.85 | G32: 21.1 | H32: =SUM(E32,F32,G32) -> 1433.24 | I32: 18504.38 | L32: 46507 | M32: =M31-I32 -> 592140.4
B33: 1200-01 - CP TERCEIROS - SEBRAE | C33: 45566 | D33: 45615 | E33: 1303.65 | F33: 260.73 | G33: 13.03 | H33: =SUM(E33,F33,G33) -> 1577.41 | I33: 18504.38 | L33: 46538 | M33: =M32-I33 -> 573636.02
B34: 1225-01 - CP TERCEIROS - SESCOOP | C34: 45505 | D34: 45554 | E34: 2659.79 | F34: 531.95 | G34: 72.34 | H34: =SUM(E34,F34,G34) -> 3264.08 | I34: 18504.38 | L34: 46568 | M34: =M33-I34 -> 555131.64
B35: 1225-01 - CP TERCEIROS - SESCOOP | C35: 45536 | D35: 45583 | E35: 2840.69 | F35: 568.13 | G35: 50.84 | H35: =SUM(E35,F35,G35) -> 3459.66 | I35: 18504.38 | L35: 46599 | M35: =M34-I35 -> 536627.26
B36: 1225-01 - CP TERCEIROS - SESCOOP | C36: 45566 | D36: 45615 | E36: 3156.99 | F36: 631.39 | G36: 31.56 | H36: =SUM(E36,F36,G36) -> 3819.94 | I36: 18504.38 | L36: 46630 | M36: =M35-I36 -> 518122.88
B37: 1646-01 - CP PATRONAL - GILRAT AJUSTADO | C37: 45505 | D37: 45553 | E37: 5476.8 | F37: 1095.36 | G37: 148.96 | H37: =SUM(E37,F37,G37) -> 6721.12 | I37: 18504.38 | L37: 46660 | M37: =M36-I37 -> 499618.5
... B41: 1708-06 - REMUNERAÇÃO DE SERV. PREST. PJ | C41: 45505 | D41: 45554 | E41: 22.44 | F41: 4.48 | G41: 0.61 | H41: =SUM(E41,F41,G41) -> 27.53 | I41: 18504.38 | L41: 46783 | M41: =M40-I41 -> 425600.98
B42: 2089-01 - IRPJ – LUCRO PRESUMIDO | C42: 1º Tri/24 | D42: 45504 | E42: 141302.75 | F42: 28260.55 | G42: 6259.71 | H42: =SUM(E42,F42,G42) -> 175823.01 | I42: 18504.38 | L42: 46812 | M42: =M41-I42 -> 407096.6
B43: 2089-01 - IRPJ – LUCRO PRESUMIDO | C43: 2º Tri/24 | D43: 45504 | E43: 280751.34 | F43: 56150.26 | G43: 12437.28 | H43: =SUM(E43,F43,G43) -> 349338.88 | I43: 18504.38 | L43: 46843 | M43: =M42-I43 -> 388592.22
B44: 2172-01 - COFINS SOBRE FATURAMENTO | C44: 45383 | D44: 45534 | E44: 48541.95 | F44: 9708.39 | G44: 1728.09 | H44: =SUM(E44,F44,G44) -> 59978.43 | I44: 18504.38 | L44: 46873 | M44: =M43-I44 -> 370087.84
B45: 2172-01 - COFINS SOBRE FATURAMENTO | C45: 45474 | D45: 45527 | E45: 8015.32 | F45: 1603.06 | G45: 285.34 | H45: =SUM(E45,F45,G45) -> 9903.72 | I45: 18504.38 | L45: 46904 | M45: =M44-I45 -> 351583.46
B46: 2172-01 - COFINS SOBRE FATURAMENTO | C46: 45505 | D46: 45560 | E46: 37955.08 | F46: 7591.01 | G46: 1032.37 | H46: =SUM(E46,F46,G46) -> 46578.46 | I46: 18504.38 | L46: 46934 | M46: =M45-I46 -> 333079.08
...

Sheet PARCELAMENTO 06062025
B3: Código Receita | C3: Apuração | D3: Vencimento | E3: Valor Principal | F3: Valor Multa | G3: Valor Juros | H3: Saldo Devedor | I3: Valor Parcela | J3: Juros | K3: Valor Total | L3: Data Venc. | M3: Amortização | O3: Dívida | P3: Pago | Q3: Saldo | R3: Juros
B4: 2089-01 - IRPJ – LUCRO PRESUMIDO | C4: 3º tri/24 | D4: 45961 | E4: 161921.29 | F4: 32384.25 | G4: 12759.39 | H4: =SUM(E4,F4,G4) -> 207064.93 | I4: 29779.51 | K4: =I4+J4 -> 29779.51 | L4: 45449 | O4: 1786770.8 | P4: =I4+I5+I6+I7+I8+I9+I10+I11+I12+I13+I14+I15+I16+I17+I18+I19 -> 476472.16 | Q4: =O4-P4 -> 1310298.6 | R4: =J5+J6+J7+J8+J9+J10+J11+J12+J13+J14+J15+J16+J17+J18+J19 -> 41566.17
B5: 2089-01 - IRPJ – LUCRO PRESUMIDO | C5: 1º tri/25 | D5: 45777 | E5: 725728.09 | F5: 145145.61 | G5: 15530.58 | H5: =SUM(E5,F5,G5) -> 886404.28 | I5: 29779.51 | J5: =K5-I5 -> 297.79 | K5: 30077.3 | L5: 45504 | M5: =H17-I4 -> 1756991.3
B6: 2172-01 - COFINS SOBRE FATURAMENTO | C6: 45627 | D6: 45681 | E6: 59792.55 | F6: 11958.51 | G6: 3079.31 | H6: =SUM(E6,F6,G6) -> 74830.37 | I6: 29779.51 | J6: =K6-I6 -> 678.97 | K6: 30458.48 | L6: 45535 | M6: =M5-I6 -> 1727211.8 | O6: AMORTIZAÇÃO DA DÍVIDA | Q6: =(Q4/O4)-1 -> -0.26666664
B7: 2172-01 - COFINS SOBRE FATURAMENTO | C7: 45689 | D7: 45741 | E7: 43910.34 | F7: 8782.06 | G7: 1405.13 | H7: =SUM(E7,F7,G7) -> 54097.53 | I7: 29779.51 | J7: =K7-I7 -> 1024.41 | K7: 30803.92 | L7: 45565 | M7: =M6-I7 -> 1697432.3
B8: 2172-01 - COFINS SOBRE FATURAMENTO | C8: 45717 | D8: 45772 | E8: 54134.52 | F8: 10826.9 | G8: 1158.47 | H8: =SUM(E8,F8,G8) -> 66119.89 | I8: 29779.51 | J8: =K8-I8 -> 1387.72 | K8: 31167.23 | L8: 45596 | M8: =M7-I8 -> 1667652.8
B9: 2172-01 - COFINS SOBRE FATURAMENTO | C9: 45748 | D9: 45800 | E9: 52797.07 | F9: 10559.41 | G9: 527.97 | H9: =SUM(E9,F9,G9) -> 63884.45 | I9: 29779.51 | J9: =K9-I9 -> 1768.9 | K9: 31548.41 | L9: 45626 | M9: =M8-I9 -> 1637873.2 | O9: IMPOSTO SOBRE SERVIÇO TOMADO
B10: 2372-01 - CSLL SOBRE FATURAMENTO | C10: 3º tri/24 | D10: 45596 | E10: 54826.86 | F10: 10965.37 | G10: 4320.35 | H10: =SUM(E10,F10,G10) -> 70112.58 | I10: 29779.51 | J10: =K10-I10 -> 2444.89 | K10: 32224.4 | L10: 45657 | M10: =M9-I10 -> 1608093.7 | O10: IMPOSTO SOBRE O FATURAMENTO
B11: 2372-01 - CSLL SOBRE FATURAMENTO | C11: 1º tri/25 | D11: 45777 | E11: 234058.66 | F11: 46811.73 | G11: 5008.85 | H11: =SUM(E11,F11,G11) -> 285879.24 | I11: 29779.51 | J11: =K11-I11 -> 2444.89 | K11: 32224.4 | L11: 45688 | M11: =M10-I11 -> 1578314.2 | O11: RETENÇÃO SOBRE DESPESAS
B12: 8109-02 - PIS SOBRE FATURAMENTO | C12: 45627 | D12: 45681 | E12: 12955.06 | F12: 2591.01 | G12: 667.18 | H12: =SUM(E12,F12,G12) -> 16213.25 | I12: 29779.51 | J12: =K12-I12 -> 2790.34 | K12: 32569.85 | L12: 45716 | M12: =M11-I12 -> 1548534.7
B13: 8109-02 - PIS SOBRE FATURAMENTO | C13: 45658 | D13: 45713 | E13: 17941.02 | F13: 3588.2 | G13: 746.34 | H13: =SUM(E13,F13,G13) -> 22275.56 | I13: 29779.51 | J13: =K13-I13 -> 3088.13 | K13: 32867.64 | L13: 45747 | M13: =M12-I13 -> 1518755.2
B14: 8109-02 - PIS SOBRE FATURAMENTO | C14: 45689 | D14: 45741 | E14: 9513.9 | F14: 1902.78 | G14: 304.44 | H14: =SUM(E14,F14,G14) -> 11721.12 | I14: 29779.51 | J14: =K14-I14 -> 3448.46 | K14: 33227.97 | L14: 45777 | M14: =M13-I14 -> 1488975.7
B15: 8109-02 - PIS SOBRE FATURAMENTO | C15: 45717 | D15: 45772 | E15: 11729.14 | F15: 2345.82 | G15: 251 | H15: =SUM(E15,F15,G15) -> 14325.96 | I15: 29779.51 | J15: =K15-I15 -> 3773.06 | K15: 33552.57 | L15: 45808 | M15: =M14-I15 -> 1459196.2
B16: 8109-02 - PIS SOBRE FATURAMENTO | C16: 45748 | D16: 45800 | E16: 11439.37 | F16: 2287.87 | G16: 114.39 | H16: =SUM(E16,F16,G16) -> 13841.63 | I16: 29779.51 | J16: =K16-I16 -> 4091.7 | K16: 33871.21 | L16: 45838 | M16: =M15-I16 -> 1429416.7
H17: =SUM(H4:H16) -> 1786770.8 | I17: 29779.51 | J17: =K17-I17 -> 4425.23 | K17: 34204.74 | L17: 45869 | M17: =M16-I17 -> 1399637.2
I18: 29779.51 | J18: =K18-I18 -> 4788.54 | K18: 34568.05 | L18: 45900 | M18: =M17-I18 -> 1369857.6
I19: 29779.51 | J19: =K19-I19 -> 5113.14 | K19: 34892.65 | L19: 45930 | M19: =M18-I19 -> 1340078.1
I20: 29779.51 | K20: =I20+J20 -> 29779.51 | L20: 45961 | M20: =M19-I20 -> 1310298.6
I21: 29779.51 | K21: =I21+J21 -> 29779.51 | L21: 45991 | M21: =M20-I21 -> 1280519.1
I22: 29779.51 | K22: =I22+J22 -> 29779.51 | L22: 46022 | M22: =M21-I22 -> 1250739.6
I23: 29779.51 | K23: =I23+J23 -> 29779.51 | L23: 46053 | M23: =M22-I23 -> 1220960.1
I24: 29779.51 | K24: =I24+J24 -> 29779.51 | L24: 46081 | M24: =M23-I24 -> 1191180.6
I25: 29779.51 | K25: =I25+J25 -> 29779.51 | L25: 46112 | M25: =M24-I25 -> 1161401.1
I26: 29779.51 | K26: =I26+J26 -> 29779.51 | L26: 46142 | M26: =M25-I26 -> 1131621.6
I27: 29779.51 | K27: =I27+J27 -> 29779.51 | L27: 46173 | M27: =M26-I27 -> 1101842.1
I28: 29779.51 | K28: =I28+J28 -> 29779.51 | L28: 46203 | M28: =M27-I28 -> 1072062.5
I29: 29779.51 | K29: =I29+J29 -> 29779.51 | L29: 46234 | M29: =M28-I29 -> 1042283
I30: 29779.51 | K30: =I30+J30 -> 29779.51 | L30: 46265 | M30: =M29-I30 -> 1012503.5
I31: 29779.51 | K31: =I31+J31 -> 29779.51 | L31: 46295 | M31: =M30-I31 -> 982724.02
... I63: 29779.7 | K63: =I63+J63 -> 29779.7 | L63: 47269 | M63: =M62-I63 -> 29779.51
I64: =SUM(I4:I63) -> 1786770.8 | J64: =SUM(J4:J63) -> 41566.17 | K64: =SUM(K4:K63) -> 1828337

Sheet PARCELAMENTO 25112025 
B3: Código Receita | C3: Apuração | D3: Vencimento | E3: Valor Principal | F3: Valor Multa | G3: Valor Juros | H3: Saldo Devedor | I3: Valor Parcela | J3: Juros | K3: Valor Total | L3: Data Venc. | M3: Amortização | O3: Dívida | P3: Pago | Q3: Saldo | R3: Juros
B4: 2372-01 - CSLL SOBRE FATURAMENTO | C4: 1º tri/25 | D4: 45747 | E4: 63265.42 | F4: 12653.08 | G4: 7079.4 | H4: =SUM(E4,F4,G4)+8299.79 -> 91297.69 | I4: 1521.62 | K4: =I4+J4 -> 1521.62 | L4: 45989 | O4: =H5 -> 91297.69 | P4: =I4+I5+I6+I7+I8+I9+I10+I11+I12 -> 13694.58 | Q4: =O4-P4 -> 77603.11 | R4: =J5+J6+J7+J8+J9+J10+J11+J12+J13+J14+J15+J16+J17+J18+J19+J20+J21+J22+J23+J24+J25+J26+J27+J28+J29 -> 744.94
H5: =H4 -> 91297.69 | I5: 1521.62 | K5: =I5+J5 -> 1521.62 | L5: 46019 | M5: =H5-I4 -> 89776.07
I6: 1521.62 | J6: =K6-I6 -> 33.77 | K6: 1555.39 | L6: 46050 | M6: =M5-I6 -> 88254.45 | O6: AMORTIZAÇÃO DA DÍVIDA | Q6: =(Q4/O4)-1 -> -0.14999919
I7: 1521.62 | J7: =K7-I7 -> 51.43 | K7: 1573.05 | L7: 46081 | M7: =M6-I7 -> 86732.83
I8: 1521.62 | J8: =K8-I8 -> 66.64 | K8: 1588.26 | L8: 46109 | M8: =M7-I8 -> 85211.21
I9: 1521.62 | J9: =K9-I9 -> 85.05 | K9: 1606.67 | L9: 46140 | M9: =M8-I9 -> 83689.59 | O9: IMPOSTO SOBRE SERVIÇO TOMADO
I10: 1521.62 | J10: =K10-I10 -> 101.64 | K10: 1623.26 | L10: 46170 | M10: =M9-I10 -> 82167.97 | O10: IMPOSTO SOBRE O FATURAMENTO
I11: 1521.62 | J11: =K11-I11 -> 117.92 | K11: 1639.54 | L11: 46201 | M11: =M10-I11 -> 80646.35 | O11: RETENÇÃO SOBRE DESPESAS
I12: 1521.62 | J12: =K12-I12 -> 134.96 | K12: 1656.58 | L12: 46231 | M12: =M11-I12 -> 79124.73
I13: 1521.62 | J13: =K13-I13 -> 153.53 | K13: 1675.15 | L13: 46262 | M13: =M12-I13 -> 77603.11
I14: 1521.62 | K14: =I14+J14 -> 1521.62 | L14: 46293 | M14: =M13-I14 -> 76081.49
I15: 1521.62 | K15: =I15+J15 -> 1521.62 | L15: 46323 | M15: =M14-I15 -> 74559.87
I16: 1521.62 | K16: =I16+J16 -> 1521.62 | L16: 46354 | M16: =M15-I16 -> 73038.25
I17: 1521.62 | K17: =I17+J17 -> 1521.62 | L17: 46384 | M17: =M16-I17 -> 71516.63
I18: 1521.62 | K18: =I18+J18 -> 1521.62 | L18: 46415 | M18: =M17-I18 -> 69995.01
I19: 1521.62 | K19: =I19+J19 -> 1521.62 | L19: 46446 | M19: =M18-I19 -> 68473.39
I20: 1521.62 | K20: =I20+J20 -> 1521.62 | L20: 46474 | M20: =M19-I20 -> 66951.77
I21: 1521.62 | K21: =I21+J21 -> 1521.62 | L21: 46505 | M21: =M20-I21 -> 65430.15
I22: 1521.62 | K22: =I22+J22 -> 1521.62 | L22: 46535 | M22: =M21-I22 -> 63908.53
I23: 1521.62 | K23: =I23+J23 -> 1521.62 | L23: 46566 | M23: =M22-I23 -> 62386.91
I24: 1521.62 | K24: =I24+J24 -> 1521.62 | L24: 46596 | M24: =M23-I24 -> 60865.29
I25: 1521.62 | K25: =I25+J25 -> 1521.62 | L25: 46627 | M25: =M24-I25 -> 59343.67
... I63: 1521.62 | K63: =I63+J63 -> 1521.62 | L63: 47784 | M63: =M62-I63 -> 1522.11
I64: =SUM(I4:I63) -> 91297.2

Sheet PARCELAMENTO SC
B3: Código Receita | C3: Apuração | D3: Vencimento | E3: Valor Principal | F3: Valor Multa | G3: Valor Juros | H3: Saldo Devedor | I3: Valor Parcela | J3: Juros | K3: Valor Total | L3: Data Venc. | M3: Amortização | N3: Status | P3: Dívida | Q3: Pago | R3: Saldo | S3: Juros
B4: ICMS-NOTIFICAÇÃO FISCAL FORA DO PRAZO | I4: 210.53 | J4: 12.67 | K4: =I4+J4 -> 223.2 | L4: 45534 | N4: Pago | P4: =I52 -> 10105.3 | Q4: =K5+K6+K7+K8+K9+K10+K11+K12+K13+K14+K15+K16+K17+K18+K19+K20+K21+K22+K23+K24+K25+K26+K27+K28+K29+K30+K31+K32 -> 6249.6 | R4: =P4-Q4 -> 3855.7 | S4: =J5+J6+J7+J8+J9+J10+J11+J12+J13+J14+J15+J16+J17+J18+J19+J20+J21+J22+J23+J24+J25+J26+J27+J28+J29+J30+J31+J32+J33+J34+J35+J36+J37+J38+J39+J40+J41+J42+J43+J44+J45+J46+J47+J48+J49+J50+J51-354.74 -> 1312.35
I5: 210.53 | J5: 12.67 | K5: =I5+J5 -> 223.2 | L5: 45565 | M5: =$P$4-I4 -> 9894.77 | N5: Pago
I6: 210.53 | J6: 12.67 | K6: =I6+J6 -> 223.2 | L6: 45595 | M6: =M5-I6 -> 9684.24 | N6: Pago | P6: AMORTIZAÇÃO DA DÍVIDA | R6: =(R4/P4)-1 -> -0.61844775
I7: 210.53 | J7: 12.67 | K7: =I7+J7 -> 223.2 | L7: 45626 | M7: =M6-I7 -> 9473.71 | N7: Pago
I8: 210.53 | J8: 12.67 | K8: =I8+J8 -> 223.2 | L8: 45656 | M8: =M7-I8 -> 9263.18 | N8: Pago
I9: 210.53 | J9: 12.67 | K9: =I9+J9 -> 223.2 | L9: 45687 | M9: =M8-I9 -> 9052.65 | N9: Pago
I10: 210.53 | J10: 12.67 | K10: =I10+J10 -> 223.2 | L10: 45716 | M10: =M9-I10 -> 8842.12 | N10: Pago
I11: 210.53 | J11: 12.67 | K11: =I11+J11 -> 223.2 | L11: 45746 | M11: =M10-I11 -> 8631.59 | N11: Pago
I12: 210.53 | J12: 12.67 | K12: =I12+J12 -> 223.2 | L12: 45777 | M12: =M11-I12 -> 8421.06 | N12: Pago
I13: 210.53 | J13: 12.67 | K13: =I13+J13 -> 223.2 | L13: 45807 | M13: =M12-I13 -> 8210.53 | N13: Pago
I14: 210.53 | J14: 12.67 | K14: =I14+J14 -> 223.2 | L14: 45838 | M14: =M13-I14 -> 8000 | N14: Pago
I15: 210.53 | J15: 12.67 | K15: =I15+J15 -> 223.2 | L15: 45868 | M15: =M14-I15 -> 7789.47 | N15: Pago
I16: 210.53 | J16: 12.67 | K16: =I16+J16 -> 223.2 | L16: 45899 | M16: =M15-I16 -> 7578.94 | N16: Pago
I17: 210.53 | J17: 12.67 | K17: =I17+J17 -> 223.2 | L17: 45930 | M17: =M16-I17 -> 7368.41 | N17: Pago
I18: 210.53 | J18: 12.67 | K18: =I18+J18 -> 223.2 | L18: 45960 | M18: =M17-I18 -> 7157.88 | N18: Pago
... I51: 210.53 | J51: 69.07 | K51: =I51+J51 -> 279.6 | L51: 46964 | M51: =M50-I51 -> 210.39 | N51: Pendente
I52: =SUM(I4:I51)-0.14 -> 10105.3

Sheet IMPOSTOS NÃO PARCELADOS
B2: JLE - IMPOSTOS EM ABERTO - NÃO PARCELADOS NA RECEITA FEDERAL
B3: Imposto | C3: 3º TRI/24 | D3: dez/24 | E3: jan/25 | F3: fev/25 | G3: mar/25 | H3: 1º TRI/25 | I3: abr/25 | J3: mai/25 | K3: jun/25 | L3: 2º TRI/25 | M3: jul/25 | N3: ago/25 | O3: set/25 | P3: 3º TRI/25 | Q3: out/25 | R3: nov/25 | S3: dez/25 | T3: 4º TRI/25 | U3: mai/23 | V3: mai/252 | W3: Total | Y3: Taxa Selic | Z3: %
B4: IRPJ | C4: 161921.29 | H4: 725728.09 | W4: =SUM(C4:T4) -> 887649.38 | Y4: 45566 | Z4: 0.0093
B5: Multa | C5: =C4*20% -> 32384.258 | H5: 76636.88 | W5: =SUM(C5:T5) -> 109021.14 | Y5: 45597 | Z5: 0.0079
B6: Juros | C6: 12759.39 | H6: 15530.58 | W6: =SUM(C6:T6) -> 28289.97 | Y6: 45627 | Z6: 0.0093
B7: TOTAL | C7: =SUBTOTAL(109,C4:C6) -> 207064.94 | H7: =SUBTOTAL(109,H4:H6) -> 817895.55 | W7: =SUM(W4,W5,W6) -> 1024960.5 | Y7: 45658 | Z7: 0.0101
B8: CSLL | C8: 54826.86 | H8: 234058.66 | W8: =SUM(C8:T8) -> 288885.52 | Y8: 45689 | Z8: 0.0099
B9: Multa | C9: =C8*20% -> 10965.372 | H9: 24716.59 | W9: =SUM(C9:T9) -> 35681.962 | Y9: 45717 | Z9: 0.0096
B10: Juros | C10: 4320.35 | H10: 5008.85 | W10: =SUM(C10:T10) -> 9329.2 | Y10: 45748 | Z10: 0.0106
B11: TOTAL | C11: =SUBTOTAL(109,C8:C10) -> 70112.582 | H11: =SUBTOTAL(109,H8:H10) -> 263784.1 | W11: =SUM(W8,W9,W10) -> 333896.68 | Z11: 0.01
B12: PIS | D12: 12955.06 | E12: 17941.02 | F12: 9513.9 | G12: 11729.14 | I12: 11439.37 | W12: =SUM(C12:V12) -> 63578.49
B13: Multa | D13: =D12*20% -> 2591.012 | E13: =E12*20% -> 3588.204 | F13: =F12*20% -> 1902.78 | G13: 1393.42 | I13: 301.99 | W13: =SUM(C13:T13) -> 9777.406
B14: Juros | D14: 667.18 | E14: 746.34 | F14: 304.44 | G14: 251 | I14: 114.39 | W14: =SUM(C14:T14) -> 2083.35
B15: TOTAL | D15: =SUBTOTAL(109,D12:D14) -> 16213.252 | E15: =SUBTOTAL(109,E12:E14) -> 22275.564 | F15: =SUBTOTAL(109,F12:F14) -> 11721.12 | G15: =SUBTOTAL(109,G12:G14) -> 13373.56 | I15: =SUBTOTAL(109,I12:I14) -> 11855.75 | J15: =SUBTOTAL(109,J12:J14) -> 0 | W15: =SUM(W12,W13,W14) -> 75439.246
B16: COFINS | D16: 59792.55 | F16: 43910.34 | G16: 54134.52 | I16: 52797.07 | W16: =SUM(C16:V16) -> 210634.48
B17: Multa | D17: =D16*20% -> 11958.51 | E17: =E16*20% -> 0 | F17: =F16*20% -> 8782.068 | G17: 6431.18 | I17: 1393.84 | W17: =SUM(C17:T17) -> 28565.598
B18: Juros | D18: 3079.31 | E18: =SUM(Z5:Z21)*E16 -> 0 | F18: 1405.13 | G18: 1158.47 | I18: 527.97 | W18: =SUM(C18:T18) -> 6170.88
B19: TOTAL | D19: =SUBTOTAL(109,D16:D18) -> 74830.37 | E19: =SUBTOTAL(109,E16:E18) -> 0 | F19: =SUBTOTAL(109,F16:F18) -> 54097.538 | G19: =SUBTOTAL(109,G16:G18) -> 61724.17 | I19: =SUBTOTAL(109,I16:I18) -> 54718.88 | J19: =SUBTOTAL(109,J16:J18) -> 0 | W19: =SUM(W16,W17,W18) -> 245370.96
C20: =C7+C11+C15+C19 -> 277177.52 | D20: =D7+D11+D15+D19 -> 91043.622 | E20: =E7+E11+E15+E19 -> 22275.564 | F20: =F7+F11+F15+F19 -> 65818.658 | G20: =G7+G11+G15+G19 -> 75097.73 | H20: =H7+H11+H15+H19 -> 1081679.6 | I20: =I7+I11+I15+I19 -> 66574.63 | J20: =J7+J11+J15+J19 -> 0 | ... T20: =T7+T11+T15+T19 -> 0 | W20: =W7+W15+W11+W19 -> 1679667.4

Sheet ACOMPANHAMENTO MENSAL
C2: 45839 | D2: 45870 | E2: 45901 | F2: 45931 | G2: 45962 | H2: 45992 | I2: 46023 | J2: 46054 | K2: 46082 | L2: 46113 | M2: 46143 | N2: 46174 | O2: 46204 | P2: 46235 | Q2: 46266
B3: FATURAMENTO | C3: 4720740.3 | D3: 3933285.2 | E3: 4298204.9 | F3: =4883322.93 -> 4883322.9 | G3: =4245011.69 -> 4245011.7 | H3: =4140927.18 -> 4140927.2 | I3: 6411342 | J3: =3588099.37 -> 3588099.4 | K3: 3598275.5 | L3: 4192838.3 | M3: 4278028.7 | N3: 3912277.6 | O3: 5882097.6 | P3: 3196894.2 | Q3: 3796974.4
B4: ISS | C4: 749.69 | D4: 555.83 | E4: 245.54 | F4: 2053.39 | G4: 614.61 | H4: 424.92 | I4: 0 | J4: 0 | K4: 0 | L4: 121.28 | M4: 0 | N4: 51.02 | O4: 119.3 | P4: 0 | Q4: 0
B5: PIS | C5: 23389.74 | D5: 23248.26 | E5: 18276.35 | F5: 19986.42 | G5: 24465.26 | H5: 20360.25 | I5: =22285.39 -> 22285.39 | J5: 0 | K5: 0 | L5: 0 | M5: 36214.15 | N5: 53315.91 | P5: 53315.91 | Q5: =16179.2 -> 16179.2
B6: COFINS | C6: 107597.6 | D6: 107299.69 | E6: 84352.37 | F6: 92271.08 | G6: 112915.75 | H6: 93969.99 | I6: =102854.7 -> 102854.7 | J6: 0 | K6: 0 | L6: 0 | M6: 100959.81 | N6: 0 | O6: 99037.19 | P6: 245472 | Q6: =74452.63 -> 74452.63
B7: IR | C7: 301206.3 | D7: 304218.36 | E7: 307712.35 | F7: 339560.64 | G7: =342956.22 -> 342956.22 | H7: 346521.61 | I7: =347930.35 -> 347930.35
B8: CSLL | C8: 99163.88 | D8: 100155.51 | E8: 101305.81 | F8: 112688.97 | G8: 113815.84 | H8: 114999.08 | I8: =117569.74 -> 117569.74
B9: TOTAL MÊS | C9: =SUM(C4:C8) -> 532107.21 | D9: =SUM(D4:D8) -> 535477.65 | E9: =SUM(E4:E8) -> 511892.42 | F9: =SUM(F4:F8) -> 566560.5 | G9: =SUM(G4:G8) -> 594767.68 | H9: =SUM(H4:H8) -> 576275.85 | I9: =SUM(I4:I8) -> 590640.18 | J9: =SUM(J4:J8) -> 0 | ... Q9: =SUM(Q4:Q8) -> 90631.83
